Workbook
Name OT: #REF!

Sheet Acerca de
C2: SOBRE ESTE DIAGRAMA DE GANTT
C4: Visualice y realice un seguimiento de sus proyectos con esta plantilla de diagrama de Gantt. Para empezar, escriba las tareas en las que está trabajando en la sección Descripción de hito y, después, escriba los detalles de cada tarea. Los datos se actualizarán automáticamente y es fácil insertar nuevas tareas o usar la barra de desplazamiento para desplazarse por la escala de tiempo.
C5: • Use Progreso para agregar la cantidad del proyecto que ha terminado agregando un número de porcentaje. • Agregue el día en que inició el proyecto en Fecha de inicio. • Complete los cálculos rellenando el número de días que necesita para completar el proyecto en el campo Nro. de días.

Sheet FEB.-22
B1: Cliente Interno | C1: Cliente | D1: Equipo | E1: Modelo/Capacidad | F1: Camion | G1: Modelo | H1: Vin / Patente | I1: VALOR NETO | J1: % | K1: SM | M1: Fecha | O1: INGENIERIA | P1: CORTE Y PLEGADO | Q1: ARMADO | R1: MONTAJE | S1: PINTURA | T1: HIDRAULICA | U1: TERMINACIONES
A2: 1277 | B2: CENTRO EQUIPOS | C2: VOLVO | D2: ALJIBE | E2: 20 M³ | F2: VOLVO | G2: VM 330 | H2: 176283 | I2: 17000000 | J2: 1 | K2: 1 | L2: OK | M2: 44596 | N2: 1 | O2: OK | P2: OK | Q2: OK | R2: OK | S2: OK | T2: OK | U2: OK
A3: 1334 | B3: ETP | C3: KAUFMANN / CMT | D3: COMBUSTIBLE | E3: 6 M³ | F3: M.BENZ | G3: 1726 | H3: 241545 | I3: 20746000 | J3: 1 | K3: 2 | L3: OK | M3: 44600 | N3: 1 | O3: OK | P3: OK | Q3: OK | R3: OK | S3: OK | T3: OK | U3: OK
A4: 1267 | B4: CENTRO EQUIPOS | C4: VOLVO | D4: CARROCERIA MINERA | E4: 6.300x2.600x4x500 + PIÑAS | F4: VOLVO | G4: FMX 420 | H4: 906687 | I4: 6900000 | J4: 1 | K4: 2 | L4: OK | M4: 44602 | N4: 1 | O4: OK | P4: OK | Q4: OK | R4: OK | S4: OK | T4: OK | U4: OK
A5: 1290 | B5: CENTRO EQUIPOS | C5: SALFA | D5: TOLVA | E5: TFR 24 M³ + PUERTA MINERA | F5: MACK | G5: GRANITE | H5: 1172 | I5: 19500000 | J5: 1 | K5: 3 | L5: OK | M5: 44606 | N5: 1 | O5: OK | P5: OK | Q5: OK | R5: OK | S5: OK | T5: OK | U5: OK
A6: 1151 | B6: CENTRO EQUIPOS | C6: CARMONA | D6: TOLVA | E6: TPI 15 M³ | F6: V.WAGEN | G6: 31330 | H6: 33260 | I6: 9800000 | J6: 1 | K6: 3 | L6: OK | M6: 44608 | N6: 1 | O6: OK | P6: OK | Q6: OK | R6: OK | S6: OK | T6: OK | U6: OK
A7: 1222 | B7: ETP | C7: KAUFMANN | D7: LUBRICADOR | E7: MIXTO | F7: M.BENZ | G7: 1726 | H7: 228012 | I7: 40300000 | J7: 1 | K7: 3 | L7: OK | M7: 44608 | N7: 1 | O7: OK | P7: OK | Q7: OK | R7: OK | S7: OK | T7: OK | U7: OK
A8: 1264 | B8: CENTRO EQUIPOS | C8: BESALCO | D8: COMBUSTIBLE | E8: 15 M³ | F8: INTER | G8: 7600 | H8: GKPH-94 | I8: 22400000 | J8: 1 | K8: 3 | L8: OK | M8: 44609 | N8: 1 | O8: OK | P8: OK | Q8: OK | R8: OK | S8: OK | T8: OK | U8: OK
A9: 1221 | B9: ETP | C9: DIFOR | D9: TOLVA | E9: TPI 14 A 15 M³ | F9: V.WAGEN | G9: 32360 | H9: 43849 | I9: 10400000 | J9: 1 | K9: 3 | L9: OK | M9: 44610 | N9: 1 | O9: OK | P9: OK | Q9: OK | R9: OK | S9: OK | T9: OK | U9: OK
A10: 1394 | B10: ETP | C10: MUNI. DE PERQUENCO | D10: TOLVA | E10: TPI 12 M³ A 14 M³ | F10: V.WAGEN | G10: 31330 | H10: 43229 | I10: 14000000 | J10: 1 | K10: 3 | L10: OK | M10: 44610 | N10: 1 | O10: OK | P10: OK | Q10: OK | R10: OK | S10: OK | T10: OK | U10: OK
A11: 1395 | B11: ETP | C11: MUNI. DE PERQUENCO | D11: TOLVA | E11: TRE 8 M³ | F11: V.WAGEN | G11: 17280 | H11: 29662 | I11: 8000000 | J11: 1 | K11: 4 | L11: OK | M11: 44614 | N11: 1 | O11: OK | P11: OK | Q11: OK | R11: OK | S11: OK | T11: OK | U11: OK
A12: 1361 | B12: ETP | C12: TRANSERIK | D12: TOLVA | E12: TPI 16 M³ A 17 M³ | F12: VOLVO | G12: VM 330 | H12: 178712 | I12: 12500000 | J12: 1 | K12: 4 | L12: OK | M12: 44614 | N12: 1 | O12: OK | P12: OK | Q12: OK | R12: OK | S12: OK | T12: OK | U12: OK
A13: 1166 | B13: CENTRO EQUIPOS | C13: SALFA | D13: TOLVA | E13: TFR 22 M³ + PUERTA MINERA | F13: RENAULT | G13: K 480 | H13: 1033 | I13: 19500000 | J13: 1 | K13: 4 | L13: OK | M13: 44617 | N13: 1 | O13: OK | P13: OK | Q13: OK | R13: OK | S13: OK | T13: OK | U13: OK
A14: 1368 | B14: ETP | C14: AUTO SUMMIT | D14: TOLVA | E14: TPI 12 M³ A 14 M³ | F14: V.WAGEN | G14: 31330 | H14: 43029 | I14: 10500000 | J14: 1 | K14: 5 | L14: OK | M14: 44620 | N14: 1 | O14: OK | P14: OK | Q14: OK | R14: OK | S14: OK | T14: OK | U14: OK
A15: 1165 | B15: CENTRO EQUIPOS | C15: SALFA | D15: TOLVA | E15: TFR 22 M³ + PUERTA MINERA | F15: RENAULT | G15: K 480 | H15: 1034 | I15: 19500000 | J15: 1 | K15: 5 | L15: OK | M15: 44622 | N15: 1 | O15: OK | P15: OK | Q15: OK | R15: OK | S15: OK | T15: OK | U15: OK
A16: 1167 | B16: CENTRO EQUIPOS | C16: SALFA | D16: TOLVA | E16: TFR 22 M³ + PUERTA MINERA | F16: RENAULT | G16: K 480 | H16: 1031 | I16: 19500000 | J16: 1 | K16: 6 | L16: OK | M16: 44628 | N16: 1 | O16: OK | P16: OK | Q16: OK | R16: OK | S16: OK | T16: OK | U16: ok
A17: 1391 | B17: ETP | C17: PORSCHE / LABEL ING. | D17: TOLVA | E17: TRE 8 M³ | F17: V.WAGEN | G17: 17230 | H17: 45907 | I17: 8500000 | J17: 1 | K17: 5 | L17: OK | M17: 44622 | N17: 1 | O17: OK | P17: OK | Q17: OK | R17: OK | S17: OK | T17: OK | U17: OK
A18: 1392 | B18: ETP | C18: PORSCHE / LABEL ING. | D18: TOLVA | E18: TRE 8 M³ | F18: V.WAGEN | G18: 17230 | H18: 46735 | I18: 8500000 | J18: 1 | K18: 5 | L18: OK | M18: 44621 | N18: 1 | O18: OK | P18: OK | Q18: OK | R18: OK | S18: OK | T18: OK | U18: OK
A19: 1323 | B19: CENTRO EQUIPOS | C19: VOLVO | D19: ALJIBE | E19: 20 M³ | F19: VOLVO | G19: VM 330 | H19: 178012 | I19: 21000000 | J19: 1 | K19: 5 | L19: OK | M19: 44620 | N19: 1 | O19: OK | P19: OK | Q19: OK | R19: OK | S19: OK | T19: OK | U19: OK
A20: 1263 | B20: CENTRO EQUIPOS | C20: SALFA / ISLA DE MAIPO | D20: ATMOSFERICO | E20: 13 M³ | F20: CHEVROLET | G20: FVR 1826 | H20: 7000008 | I20: 24500000 | J20: 1 | K20: 5 | L20: OK | M20: 44620 | N20: 1 | O20: OK | P20: OK | Q20: OK | R20: OK | S20: OK | T20: OK | U20: OK
A22: 1330 | B22: CENTRO EQUIPOS | C22: DOCALL | D22: TOLVA | E22: TRE 4 M³ A 5 M³ CON NICHO | F22: V.WAGEN | G22: 9-170 | H22: 37083 | I22: 8000000 | J22: 1 | K22: Solo Para Bono | M22: 44592 | N22: 1
G24: Total equipo Febrero | H24: =SUM(N2:N23) -> 20 | I24: =SUM(I2:I20) -> 313046000
G26: Equ. Fab. Y Facturado | I26: =SUMIF(J2:J20,J26,I2:I20) -> 313046000 | J26: 1
G27: Equ. Facturado semanal | H27: 31/01 al 4/02 | I27: =SUMIF($K$2:$K$23,J27,$I$2:$I$23) -> 17000000 | J27: 1
G28: Equ. Facturado semanal | H28: 7/02 al 11/02 | I28: =SUMIF($K$2:$K$23,J28,$I$2:$I$23) -> 27646000 | J28: 2
G29: Equ. Facturado semanal | H29: 14/02 al 18/02 | I29: =SUMIF($K$2:$K$23,J29,$I$2:$I$23) -> 116400000 | J29: 3
G30: Equ. Facturado semanal | H30: 21/02 al 25/02 | I30: =SUMIF($K$2:$K$23,J30,$I$2:$I$23) -> 40000000 | J30: 4
G31: Equ. Facturado semanal | H31: 28/02 al 4/03 | I31: =SUMIF($K$2:$K$23,J31,$I$2:$I$23) -> 92500000 | J31: 5
G32: Equ. Facturado semanal | H32: 7/03 al 11/03 | I32: =SUMIF($K$2:$K$23,J32,$I$2:$I$23) -> 19500000 | J32: 6
G34: Mix de Producto | I34: Cliente Interno
G35: ALJIBE | H35: =SUMIF($D$2:$D$21,G35,$N$2:$N$21) -> 2 | I35: ETP | J35: =SUMIF($B$2:$B$21,I35,$N$2:$N$21) -> 9
G36: ATMOSFERICO | H36: =SUMIF($D$2:$D$21,G36,$N$2:$N$21) -> 1 | I36: CENTRO EQUIPOS | J36: =SUMIF($B$2:$B$21,I36,$N$2:$N$21) -> 10
G37: CARROCERIA MINERA | H37: =SUMIF($D$2:$D$21,G37,$N$2:$N$21) -> 1
G38: COMBUSTIBLE | H38: =SUMIF($D$2:$D$21,G38,$N$2:$N$21) -> 2
G39: COMBUSTIBLE AVIACION | H39: =SUMIF($D$2:$D$21,G39,$N$2:$N$21) -> 0
G40: LUBRICADOR | H40: =SUMIF($D$2:$D$21,G40,$N$2:$N$21) -> 1
G41: TOLVA | H41: =SUMIF($D$2:$D$21,G41,$N$2:$N$21) -> 12
H43: =SUM(H35:H42) -> 19 | J43: =SUM(J35:J42) -> 19
B46: Distribucion de Hora Extra
B47: Hora Extra Entre semana | C47: Sabado | D47: Domingo | E47: Feriado | F47: Total Hora Extra
...

Sheet ENE.-22
A1: OT | B1: Cliente Interno | C1: Cliente | D1: Equipo | E1: Modelo/Capacidad | F1: Camion | G1: Modelo | H1: Vin / Patente | I1: VALOR NETO | J1: % | K1: SM | M1: Fecha
A2: 1163 | B2: CENTRO EQUIPOS | C2: SALFA | D2: TOLVA | E2: TFR 22 M³ + PUERTA MINERA | F2: RENAULT | G2: K 480 | H2: 1015 | I2: 19500000 | J2: 1 | K2: 1 | L2: OK | M2: 44567 | N2: 1
A3: 1206 | B3: CENTRO EQUIPOS | C3: PORSCHE / LAURO | D3: ALJIBE | E3: 20 M³ INOX | F3: V.WAGEN | G3: 32360 | H3: 18288 | I3: 25000000 | J3: 1 | K3: 2 | L3: OK | M3: 44567 | N3: 1
A4: 1285 | B4: CENTRO EQUIPOS | C4: OSERVIN | D4: TOLVA | E4: TRE 10 M³ A 12 M³ INOX | F4: V.WAGEN | G4: 32360 | H4: 32230 | I4: 12500000 | J4: 1 | K4: 2 | L4: OK | M4: 44567 | N4: 1
A5: 1164 | B5: CENTRO EQUIPOS | C5: SALFA | D5: TOLVA | E5: TFR 22 M³ + PUERTA MINERA | F5: RENAULT | G5: K 480 | H5: 1013 | I5: 19500000 | J5: 1 | K5: 2 | L5: OK | M5: 44572 | N5: 1
A6: 1214 | B6: ETP | C6: KAUFMANN | D6: TOLVA | E6: TPI 14 M³ | F6: M.BENZ | G6: 3131 | H6: 247332 | I6: 10500000 | J6: 1 | K6: 2 | L6: OK | M6: 44575 | N6: 1
A7: 1248 | B7: ETP | C7: KAUFMANN | D7: TOLVA | E7: TPI 14 M³ | F7: M.BENZ | G7: 3131 | H7: 242805 | I7: 10500000 | J7: 1 | K7: 3 | L7: OK | M7: 44578 | N7: 1
A8: 1205 | B8: CENTRO EQUIPOS | C8: VOLVO / M.VALDIVIA | D8: ALJIBE | E8: 20 M³ INOX | F8: VOLVO | G8: VM 330 | H8: 176434 | I8: 25000000 | J8: 1 | K8: 3 | L8: OK | M8: 44582 | N8: 1
A9: 1249 | B9: ETP | C9: KAUFMANN | D9: TOLVA | E9: TPI 12 M³ A 14 M³ | F9: M.BENZ | G9: 3131 | H9: 247272 | I9: 10500000 | J9: 1 | K9: 3 | L9: OK | M9: 44582 | N9: 1
A10: 1219 | B10: ETP | C10: DIFOR | D10: TOLVA | E10: TPI 14 A 15 M³ | F10: V.WAGEN | G10: 32360 | H10: 38041 | I10: 10400000 | J10: 1 | K10: 4 | L10: OK | M10: 44586 | N10: 1
A11: 1012 | B11: ETP | C11: MOVITEC | D11: LUBRICADOR | E11: LUBRICADOR CERRADO | F11: VOLVO | G11: VM 330 | H11: 173913 | I11: 101129090 | J11: 1 | K11: 4 | L11: OK | M11: 44586 | N11: 1
A12: 1207 | B12: ETP | C12: JUAN CONTRERAS | D12: COMBUSTIBLE | E12: 10 M³ | F12: V.WAGEN | G12: 17230 | H12: 22451 | I12: 20000000 | J12: 1 | K12: 4 | L12: OK | M12: 44587 | N12: 1
A13: 1289 | B13: CENTRO EQUIPOS | C13: SALFA | D13: TOLVA | E13: TFR 24 M³ + PUERTA MINERA | F13: MACK | G13: GRANITE | H13: 1177 | I13: 19500000 | J13: 1 | K13: 4 | L13: OK | M13: 44587 | N13: 1
A14: 1278 | B14: CENTRO EQUIPOS | C14: KOVACS | D14: ALJIBE | E14: 10 M³ INOX + MOTOBOMBA | F14: CHEVROLET | G14: FVR 1724 | H14: 7000051 | I14: 14900000 | J14: 1 | K14: 4 | L14: OK | M14: 44587 | N14: 1
A15: 1245 | B15: CENTRO EQUIPOS | C15: SCANIA | D15: ALJIBE | E15: 15 M³ + ESCALERA MELL | F15: SCANIA | G15: P 410 | H15: 3991968 | I15: 16000000 | J15: 1 | K15: 5 | L15: OK | M15: 44593 | N15: 1
A16: 1291 | B16: CENTRO EQUIPOS | C16: SALFA | D16: TOLVA | E16: TFR 24 M³ + PUERTA MINERA | F16: MACK | G16: GRANITE | H16: 1178 | I16: 19500000 | J16: 1 | K16: 5 | L16: OK | M16: 44593 | N16: 1
A17: 1261 | B17: ETP | C17: PORSCHE | D17: TOLVA | E17: TPI 14 M³ | F17: V.WAGEN | G17: 31330 | H17: 42727 | I17: 9500000 | J17: 1 | K17: 5 | L17: OK | M17: 44593 | N17: 1
A18: 1351 | B18: ETP | C18: DIFOR | D18: TOLVA | E18: TPI 14 A 15 M³ | F18: V.WAGEN | G18: 32360 | H18: 43857 | I18: 10400000 | J18: 1 | K18: 5 | L18: OK | M18: 44594 | N18: 1
A19: 1201 | B19: ETP | C19: J.VERDEJO - PTO | D19: ATMOSFERICO | E19: 8 M³ | F19: V.WAGEN | G19: 17220 | H19: CYWY-86 | I19: 18500000 | J19: 1 | K19: 5 | L19: OK | M19: 44595 | N19: 1
A20: 1247 | B20: ETP | C20: KAUFMANN | D20: TOLVA | E20: TPI 12 M³ A 14 M³ | F20: M.BENZ | G20: 3131 | H20: 247332 | I20: 10500000 | J20: 1 | K20: 5 | L20: OK | M20: 44599 | N20: 1
A21: 1367 | B21: ETP | C21: AUTO SUMMIT | D21: TOLVA | E21: TPI 12 M³ A 14 M³ | F21: V.WAGEN | G21: 31330 | H21: 43194 | I21: 10500000 | J21: 1 | K21: 5 | L21: OK | M21: 44606 | N21: 1
G24: Total equipo Enero | H24: =SUM(N2:N21) -> 20 | I24: =SUM(I2:I21) -> 393829090
G26: Equ. Fab. Y Facturado | I26: =SUMIF(J2:J23,J26,I2:I23) -> 393829090 | J26: 1
G27: Equ. Facturado semanal | H27: 3/01 al 7/01 | I27: =SUMIF($K$2:$K$21,J27,$I$2:$I$21) -> 19500000 | J27: 1
G28: Equ. Facturado semanal | H28: 10/01 al 14/01 | I28: =SUMIF($K$2:$K$21,J28,$I$2:$I$21) -> 67500000 | J28: 2
G29: Equ. Facturado semanal | H29: 17/01 al 21/01 | I29: =SUMIF($K$2:$K$21,J29,$I$2:$I$21) -> 46000000 | J29: 3
G30: Equ. Facturado semanal | H30: 24/01 al 28/01 | I30: =SUMIF($K$2:$K$21,J30,$I$2:$I$21) -> 165929090 | J30: 4
G31: Equ. Facturado semanal | H31: 31/01 al 4/02 | I31: =SUMIF($K$2:$K$19,J31,$I$2:$I$20) -> 73900000 | J31: 5
G33: Mix de Producto | I33: Cliente Interno
G34: ALJIBE | H34: =SUMIF($D$2:$D$21,G34,$N$2:$N$21) -> 4 | I34: ETP | J34: =SUMIF($B$2:$B$21,I34,$N$2:$N$21) -> 11
G35: ATMOSFERICO | H35: =SUMIF($D$2:$D$21,G35,$N$2:$N$21) -> 1 | I35: CENTRO EQUIPOS | J35: =SUMIF($B$2:$B$21,I35,$N$2:$N$21) -> 9
G36: CARROCERIA MINERA | H36: =SUMIF($D$2:$D$21,G36,$N$2:$N$21) -> 0
G37: COMBUSTIBLE | H37: =SUMIF($D$2:$D$21,G37,$N$2:$N$21) -> 1
G38: COMBUSTIBLE AVIACION | H38: =SUMIF($D$2:$D$21,G38,$N$2:$N$21) -> 0
G39: LUBRICADOR | H39: =SUMIF($D$2:$D$21,G39,$N$2:$N$21) -> 1
G40: TOLVA | H40: =SUMIF($D$2:$D$21,G40,$N$2:$N$21) -> 13
H42: =SUM(H34:H41) -> 20 | J42: =SUM(J34:J41) -> 20
B46: Distribucion de Hora Extra
B47: Hora Extra Entre semana | C47: Sabado | D47: Domingo | E47: Feriado | F47: Total Hora Extra
B48: 144 | C48: 462 | D48: 67 | E48: 0 | F48: =SUM(A48:E48) -> 673

Sheet MAR-22
A1: Prioridad | B1: OT | C1: Cliente Interno | D1: Cliente | E1: Equipo | F1: Modelo/Capacidad | G1: Camion | H1: Modelo | I1: Vin / Patente | J1: VALOR NETO | K1: % | L1: SM | N1: Fecha | P1: INGENIERIA | Q1: Dia | R1: CORTE Y PLEGADO | S1: Dia | T1: ARMADO | U1: Dia | V1: MONTAJE | W1: Dia | X1: PINTURA | Y1: Dia | Z1: HIDRAULICA | AA1: Dia | AB1: TERMINACIONES | AC1: Dia | AD1: PTO | AE1: BBA H | AF1: CILINDRO | AG1: DERIVADORA | AH1: MOTOR H | AI1: BBA CENT. | AJ1: BBA VACIO
A2: Entregada | B2: 1170 | C2: CENTRO EQUIPOS | D2: SALFA | E2: TOLVA | F2: TFR 22 M³ + PUERTA MINERA | G2: RENAULT | H2: K 480 | I2: 1036 | J2: 19500000 | K2: 1 | L2: 3 | M2: OK | N2: 44638 | O2: 1 | P2: OK | Q2: - | R2: OK | S2: - | T2: OK | U2: - | V2: OK | W2: 4 | X2: OK | Y2: 1 | Z2: OK | AA2: 1 | AB2: OK | AC2: 1
A3: Entregada | B3: 1292 | C3: CENTRO EQUIPOS | D3: SALFA | E3: TOLVA | F3: TFR 24 M³ + PUERTA MINERA | G3: MACK | H3: GRANITE | I3: 1212 | J3: 19500000 | K3: 1 | L3: 4 | M3: OK | N3: 44644 | O3: 1 | P3: OK | Q3: - | R3: OK | S3: - | T3: OK | U3: 3.5 | V3: OK | W3: 5.5 | X3: OK | Y3: 1 | Z3: OK | AA3: 1 | AB3: OK | AC3: 1
A4: Entregada | B4: 1397 | C4: ETP | D4: DIFOR | E4: TOLVA | F4: 15 M³ XAR | G4: MAN | H4: TGS 33.480 | I4: 892877 | J4: 19000000 | K4: 1 | L4: 5 | M4: OK | N4: 44651 | O4: 1 | P4: OK | Q4: - | R4: OK | S4: - | T4: OK | U4: 4 | V4: OK | W4: 5 | X4: OK | Y4: 1 | Z4: OK | AA4: 1 | AB4: OK | AC4: 1.5
A5: Entregada | B5: 1293 | C5: CENTRO EQUIPOS | D5: SALFA | E5: TOLVA | F5: TFR 24 M³ + PUERTA MINERA | G5: MACK | H5: GRANITE | I5: 1212 | J5: 19500000 | K5: 1 | L5: 5 | M5: OK | N5: 44650 | O5: 1 | P5: OK | Q5: - | R5: OK | S5: - | T5: OK | U5: 6.5 | V5: OK | W5: 6 | X5: OK | Y5: 1 | Z5: OK | AA5: 1 | AB5: OK | AC5: 1.5
A6: Entregada | B6: 1294 | C6: CENTRO EQUIPOS | D6: SALFA | E6: TOLVA | F6: TFR 24 M³ + PUERTA MINERA | G6: MACK | H6: GRANITE | I6: 1238 | J6: 19500000 | K6: 1 | L6: 5 | M6: OK | N6: 44652 | O6: 1 | P6: OK | Q6: - | R6: OK | S6: - | T6: OK | U6: 4.5 | V6: OK | W6: 5.5 | X6: OK | Y6: 1 | Z6: OK | AA6: 1 | AB6: OK | AC6: 1.5
A7: Entregada | B7: 1335 | C7: CENTRO EQUIPOS | D7: OSERVIM | E7: TOLVA | F7: TRE 10 M³ A 12 M³ INOX | G7: V.WAGEN | H7: 32360 | I7: 37931 | J7: 14900000 | K7: 1 | L7: 6 | M7: OK | N7: 44656 | O7: 1 | P7: OK | Q7: - | R7: OK | S7: 1.5 | T7: OK | U7: 4 | V7: OK | W7: 7.5 | X7: OK | Y7: 1 | Z7: OK | AA7: 1 | AB7: OK | AC7: 1
A8: Entregada | B8: 1250 | C8: ETP | D8: KAUFMANN | E8: TOLVA | F8: TPI 12 M³ A 14 M³ | G8: M.BENZ | H8: 3131 | I8: 247645 | J8: 10500000 | K8: 1 | L8: 6 | M8: OK | N8: 44659 | O8: 1 | P8: OK | Q8: - | R8: OK | S8: 1.5 | T8: OK | U8: 2.5 | V8: OK | W8: 3 | X8: OK | Y8: 1 | Z8: OK | AA8: 1 | AB8: OK | AC8: 1
A9: Entregada | B9: 1295 | C9: CENTRO EQUIPOS | D9: SALFA | E9: TOLVA | F9: TFR 24 M³ + PUERTA MINERA | G9: MACK | H9: GRANITE | I9: 1214 | J9: 19500000 | K9: 1 | L9: 4 | M9: OK | N9: 44645 | O9: 1 | P9: OK | Q9: - | R9: OK | S9: - | T9: OK | U9: 4 | V9: OK | W9: 3 | X9: OK | Y9: 1 | Z9: OK | AA9: 1 | AB9: OK | AC9: 1.5
A10: Entregada | B10: 1336 | C10: CENTRO EQUIPOS | D10: OSERVIM | E10: TOLVA | F10: TRE 10 M³ A 12 M³ INOX | G10: V.WAGEN | H10: 32360 | I10: 38204 | J10: 14900000 | K10: 1 | L10: 6 | M10: OK | N10: 44659 | O10: 1 | P10: OK | Q10: - | R10: OK | S10: 1.5 | T10: OK | U10: 5 | V10: OK | W10: 5 | X10: OK | Y10: 1 | Z10: OK | AA10: 1 | AB10: OK | AC10: 1
A11: Entregada | B11: 1362 | C11: ETP | D11: TRANSERIK | E11: TOLVA | F11: TPI 16 M³ A 17 M³ | G11: VOLVO | H11: VM 330 | I11: 177404 | J11: 12500000 | K11: 1 | L11: 6 | M11: OK | N11: 44655 | O11: 1 | P11: OK | Q11: - | R11: OK | S11: 1.5 | T11: OK | U11: 2.5 | V11: OK | W11: 3 | X11: OK | Y11: 1 | Z11: OK | AA11: 1 | AB11: OK | AC11: 1
A12: Entregada | B12: 1398 | C12: ETP | D12: PORSCHE | E12: TOLVA | F12: TRE 6 M³ A 8 M³ | G12: V.WAGEN | H12: 17280 | I12: 42668 | J12: 8500000 | K12: 1 | L12: 6 | M12: OK | N12: 44657 | O12: 1 | P12: OK | Q12: - | R12: OK | S12: 1 | T12: OK | U12: 2 | V12: OK | W12: 4 | X12: OK | Y12: 1 | Z12: OK | AA12: 1 | AB12: OK | AC12: 1
A13: Entregada | B13: 1168 | C13: CENTRO EQUIPOS | D13: SALFA | E13: TOLVA | F13: TFR 22 M³ + PUERTA MINERA | G13: RENAULT | H13: K 480 | I13: 1032 | J13: 19500000 | K13: 1 | L13: 3 | M13: OK | N13: 44635 | O13: 1 | P13: OK | Q13: - | R13: OK | S13: - | T13: OK | U13: - | V13: OK | W13: - | X13: OK | Y13: - | Z13: OK | AA13: - | AB13: OK | AC13: -
A14: Entregada | B14: 1169 | C14: CENTRO EQUIPOS | D14: SALFA | E14: TOLVA | F14: TFR 22 M³ + PUERTA MINERA | G14: RENAULT | H14: K 480 | I14: 1035 | J14: 19500000 | K14: 1 | L14: 3 | M14: OK | N14: 44636 | O14: 1 | P14: OK | Q14: - | R14: OK | S14: - | T14: OK | U14: - | V14: OK | W14: - | X14: OK | Y14: - | Z14: OK | AA14: - | AB14: OK | AC14: -
A15: Entregada | B15: 1220 | C15: ETP | D15: DIFOR | E15: TOLVA | F15: TPI 14 A 15 M³ | G15: V.WAGEN | H15: 32360 | I15: 38030 | J15: 10400000 | K15: 1 | L15: 2 | M15: OK | N15: 44627 | O15: 1 | P15: OK | Q15: - | R15: OK | S15: - | T15: OK | U15: - | V15: OK | W15: - | X15: OK | Y15: - | Z15: OK | AA15: - | AB15: OK | AC15: -
A16: Entregada | B16: 1402 | C16: ETP | D16: CHILE ARIDOS | E16: TOLVA | F16: TPI 14 M³ + PUERTA MINERA | G16: VOLVO | H16: VM 330 | I16: 178413 | J16: 11500000 | K16: 1 | L16: 3 | M16: OK | N16: 44635 | O16: 1 | P16: OK | Q16: - | R16: OK | S16: - | T16: OK | U16: - | V16: OK | W16: - | X16: OK | Y16: - | Z16: OK | AA16: - | AB16: OK | AC16: -
A17: Entregada | B17: 1328 | C17: CENTRO EQUIPOS | D17: CARMONA | E17: ALJIBE | F17: 20 M³ | G17: V.WAGEN | H17: 32360 | I17: 38208 | J17: 23500000 | K17: 1 | L17: 5 | M17: OK | N17: 44650 | O17: 1 | P17: OK | Q17: - | R17: OK | S17: - | T17: OK | U17: 3.5 | V17: OK | W17: 5.5 | X17: OK | Y17: 1.5 | Z17: OK | AA17: 5 | AB17: OK | AC17: 2
A18: Entregada | B18: 1154 | C18: CENTRO EQUIPOS | D18: MAESTRANZA ALEMANIA | E18: LUBRICADOR | F18: FURGON CERRADO | G18: M.BENZ | H18: 3342 | I18: 535548 | J18: 188843650 | K18: 1 | L18: 6 | M18: OK | N18: 44659 | O18: 1 | P18: OK | Q18: - | R18: OK | S18: - | T18: OK | U18: - | V18: OK | W18: - | X18: OK | Z18: OK | AA18: - | AB18: OK
A19: Entregada | B19: 1176 | C19: ETP | D19: USIMECA | E19: ATMOSFERICO | F19: 14.5 + 1 M³ | G19: SCANIA | H19: P 410 | I19: 3994744 | J19: 27250000 | K19: 1 | L19: 3 | M19: OK | N19: 44638 | O19: 0.5 | P19: OK | Q19: - | R19: OK | S19: - | T19: OK | U19: - | V19: OK | W19: - | X19: OK | Y19: - | Z19: OK | AB19: OK
A20: Entregada | B20: 1241 | C20: ETP | D20: JUAN CONTRERAS | E20: ALJIBE | F20: 20 M³ INOX | G20: V.WAGEN | H20: 31330 | I20: 33731 | J20: 27000000 | K20: 1 | L20: 6 | M20: OK | N20: 44659 | O20: 1 | P20: OK | Q20: - | R20: OK | S20: - | T20: OK | U20: 4 | V20: OK | W20: 4 | X20: OK | Y20: 1.5 | Z20: OK | AA20: 5 | AB20: OK | AC20: 1.5
A21: Entregada | B21: 1244 | C21: CENTRO EQUIPOS | D21: SALFA | E21: COMBUSTIBLE AVIACION | F21: JET A1 10 M³ | G21: CHEVROLET | H21: FVR 1826 | I21: 7000354 | J21: 130000000 | K21: 1 | L21: 5 | M21: OK | N21: 44652 | O21: 1 | P21: OK | Q21: - | R21: OK | S21: - | T21: OK | U21: - | V21: OK | W21: - | X21: OK | Y21: - | Z21: OK | AA21: - | AB21: OK | AC21: -
A22: Entregada | B22: 1268 | C22: CENTRO EQUIPOS | D22: VOLVO / PATRICIO ALVARADO | E22: ALJIBE | F22: 20 M³ INOX | G22: VOLVO | H22: VM 330 | I22: 178609 | J22: 23000000 | K22: 1 | L22: 4 | M22: OK | N22: 44646 | O22: 1 | P22: OK | Q22: - | R22: OK | S22: - | T22: OK | U22: - | V22: OK | W22: - | X22: OK | Y22: - | Z22: OK | AA22: - | AB22: OK | AC22: 2
A23: Entregada | B23: 1348 | C23: ETP | D23: KAUFMANN | E23: COMBUSTIBLE | F23: 6 M³ + 1 M³ ADDBLUE | G23: M.BENZ | H23: 1419 | I23: 236737 | J23: 32000000 | K23: 1 | L23: 4 | M23: OK | N23: 44641 | O23: 1 | P23: OK | Q23: - | R23: OK | S23: - | T23: OK | U23: - | V23: OK | W23: - | X23: OK | Y23: 1 | Z23: OK | AA23: - | AB23: OK | AC23: -
A24: Entregada | B24: 1401 | C24: ETP | D24: MUNI. DE LOS ALAMOS | E24: ATMOSFERICO | F24: 8 M³ + 2 M³ | G24: HINO | H24: 1726 | I24: 11353 | J24: 20000000 | K24: 1 | L24: 2 | M24: OK | N24: 44629 | O24: 1 | P24: OK | Q24: - | R24: OK | S24: - | T24: OK | U24: - | V24: OK | W24: - | X24: OK | Y24: - | Z24: OK | AA24: - | AB24: OK | AC24: -
A27: Entregada | B27: PTO 97 | C27: CENTRO EQUIPOS | D27: MAESTRANZA ALEMANIA | E27: COMBUSTIBLE | F27: 20 M³ | G27: M.BENZ | H27: 3324 | I27: - | J27: - | K27: 1 | L27: Solo Para Bono | M27: OK | N27: 44638 | O27: 0.5 | P27: OK | Q27: - | R27: OK | S27: - | T27: OK | U27: - | V27: OK | W27: - | X27: OK | Y27: - | Z27: OK | AA27: - | AB27: OK | AC27: -
C49: Mix de Producto | E49: Cliente Interno | H49: Total equipo Marzo | I49: =SUM(O2:O47) -> 23 | J49: =SUM(J2:J47) -> 710293650 | K49: =SUM(P49:AB49) -> 1 | P49: 0.03 | R49: 0.1 | T49: 0.3 | V49: 0.3 | X49: 0.1 | Z49: 0.12 | AB49: 0.05
C50: ALJIBE | D50: =SUMIF($E$2:$E$47,C50,$O$2:$O$47) -> 3 | E50: ETP | F50: =SUMIF($C$2:$C$47,E50,$O$2:$O$51) -> 9.5 | M50: Equipo Fab. hasta
C51: ATMOSFERICO | D51: =SUMIF($E$2:$E$47,C51,$O$2:$O$47) -> 1.5 | E51: CENTRO EQUIPOS | F51: =SUMIF($C$2:$C$47,E51,$O$2:$O$51) -> 13.5 | H51: Equ. Fab. Y Facturado | J51: =SUMIF(K2:K47,K51,J2:J47) -> 710293650 | K51: 1 | N51: =SUMIF($K$2:$K$47,K51,$O$2:$O$47) -> 23
C52: CARROCERIA MINERA | D52: =SUMIF($E$2:$E$47,C52,$O$2:$O$47) -> 0 | H52: Equ. Facturado semanal | I52: 28/02 al 04/03 | J52: =SUMIF($L$2:$L$47,K52,$J$2:$J$47) -> 0 | K52: 1
C53: COMBUSTIBLE | D53: =SUMIF($E$2:$E$47,C53,$O$2:$O$47) -> 1.5 | H53: Equ. Facturado semanal | I53: 07/03 a 11/03 | J53: =SUMIF($L$2:$L$47,K53,$J$2:$J$47) -> 30400000 | K53: 2
C54: COMBUSTIBLE AVIACION | D54: =SUMIF($E$2:$E$47,C54,$O$2:$O$47) -> 1 | H54: Equ. Facturado semanal | I54: 14/03 a 18/03 | J54: =SUMIF($L$2:$L$47,K54,$J$2:$J$47) -> 97250000 | K54: 3
C55: LUBRICADOR | D55: =SUMIF($E$2:$E$47,C55,$O$2:$O$47) -> 1 | H55: Equ. Facturado semanal | I55: 21/03 a 25/03 | J55: =SUMIF($L$2:$L$47,K55,$J$2:$J$47) -> 94000000 | K55: 4
C56: TOLVA | D56: =SUMIF($E$2:$E$47,C56,$O$2:$O$47) -> 15 | H56: Equ. Facturado semanal | I56: 28/03 a 01/04 | J56: =SUMIF($L$2:$L$47,K56,$J$2:$J$47) -> 211500000 | K56: 5
H57: Equ. Facturado semanal | I57: 04/04 A 08/04 | J57: =SUMIF($L$2:$L$47,K57,$J$2:$J$47) -> 277143650 | K57: 6
C59: Total | D59: =SUM(D50:D58) -> 23 | E59: Total | F59: =SUM(F50:F58) -> 23
A60: Observaciones | I60: Atrasos por Areas | J60: Motivos de Atrasos
A61: 44621 | B61: Mar
A62: =+A61+1 -> 44622 | B62: Mie
A63: =+A62+1 -> 44623 | B63: Jue
A64: =+A63+1 -> 44624 | B64: Vie
...

Sheet ABR-22
A1: Prioridad | B1: OT | C1: Cliente Interno | D1: Cliente | E1: Equipo | F1: Modelo/Capacidad | G1: Camion | H1: Modelo | I1: Vin / Patente | J1: VALOR NETO | K1: % | L1: SM | N1: Fecha | P1: INGENIERIA | Q1: Dia | R1: CORTE Y PLEGADO | S1: Dia | T1: ARMADO | U1: Dia | V1: MONTAJE | W1: Dia | X1: PINTURA | Y1: Dia | Z1: HIDRAULICA | AA1: Dia | AB1: TERMINACIONES | AC1: Dia | AD1: PTO | AE1: STOCK | AF1: BBA H | AG1: STOCK | AH1: CILINDRO | AI1: STOCK | AJ1: DERIVADORA | AK1: MOTOR H | AL1: BBA CENT. | AM1: BBA VACIO | AN1: Bomba Comb. | AO1: Stock | AP1: Cuenta Litro | AQ1: Stock | AR1: Kit Combustible | AS1: Stock | AT1: Carrete | AU1: Stock | AV1: Manguera | AW1: Stock | AX1: Pistola | AY1: Stock | AZ1: Microfiltro | BA1: STOCK | BB1: Pintura | BC1: Stock | BD1: Acero
A2: Entregada | B2: 1191 | C2: CENTRO EQUIPOS | D2: SALFA | E2: TOLVA | F2: TFR 24 M³ + PUERTA MINERA | G2: MACK | H2: GRANITE | I2: 1232 | J2: 19500000 | K2: 1 | L2: 3 | M2: OK | N2: 44673 | O2: 1 | P2: OK | Q2: - | R2: OK | S2: 2.5 | T2: OK | U2: 4 | V2: OK | W2: 3 | X2: OK | Y2: 1 | Z2: OK | AA2: 1 | AB2: OK | AC2: 1 | AD2: INCORPORADO | AE2: SI | AF2: Bezares 120 | AG2: SI | AH2: Hyva 179-5 | AI2: guia 2623 Hyva | BB2: 4.5 GL. | BC2: planta | BD2: PLANTA
A3: Entregada | B3: 1192 | C3: CENTRO EQUIPOS | D3: SALFA | E3: TOLVA | F3: TFR 24 M³ + PUERTA MINERA | G3: MACK | H3: GRANITE | I3: 1222 | J3: 19500000 | K3: 1 | L3: 4 | M3: OK | N3: 44676 | O3: 1 | P3: OK | Q3: - | R3: OK | S3: 2.5 | T3: OK | U3: 7 | V3: OK | W3: 3.5 | X3: OK | Y3: 1 | Z3: OK | AA3: 1 | AB3: OK | AC3: 1 | AD3: INCORPORADO | AE3: SI | AF3: Bezares 120 | AG3: SI | AH3: Hyva 179-5 | AI3: guia 2649 Hyva | BB3: 4.5 GL. | BC3: planta | BD3: PLANTA
A4: Entregada | B4: 1152 | C4: CENTRO EQUIPOS | D4: CARMONA | E4: TOLVA | F4: TPI 14 M³ | G4: V.WAGEN | H4: 31330 | I4: 47670 | J4: 9800000 | K4: 1 | L4: 1 | M4: OK | N4: 44657 | O4: 1 | P4: OK | Q4: 1 | R4: OK | S4: 1 | T4: OK | U4: 3.5 | V4: OK | W4: 3 | X4: OK | Y4: 0.5 | Z4: OK | AA4: 1 | AB4: OK | AC4: 1 | AD4: BEZARES | AE4: SI | AF4: Bezares 80 | AG4: SI | AH4: Hyva 137-3 | AI4: guia 2623 Hyva | BB4: 3 GL | BC4: planta | BD4: PLANTA
A5: Entregada | B5: 1344 | C5: ETP | D5: PORSCHE / QUILIN | E5: TOLVA | F5: TPI 14 M³ | G5: V.WAGEN | H5: 31330 | I5: 37058 | J5: 10490000 | K5: 1 | L5: 2 | M5: OK | N5: 44665 | O5: 1 | P5: OK | Q5: 1 | R5: OK | S5: 1.5 | T5: OK | U5: 2 | V5: OK | W5: 2.5 | X5: OK | Y5: 0.5 | Z5: OK | AA5: 1 | AB5: OK | AC5: 1 | AD5: INCORPORADO | AE5: SI | AF5: Bezares 80 | AG5: SI | AH5: Hyva 137-3 | AI5: guia 2647 Hyva | BB5: 3 GL | BC5: PLANTA | BD5: PLANTA
A6: Entregada | B6: 1345 | C6: ETP | D6: PORSCHE / QUILIN | E6: TOLVA | F6: TPI 14 M³ | G6: V.WAGEN | H6: 31330 | I6: 38199 | J6: 10490000 | K6: 1 | L6: 2 | M6: OK | N6: 44665 | O6: 1 | P6: OK | Q6: 1 | R6: OK | S6: 1.5 | T6: OK | U6: 2.5 | V6: OK | W6: 3 | X6: OK | Y6: 1 | Z6: OK | AA6: 1.5 | AB6: OK | AC6: 1 | AD6: INCORPORADO | AE6: SI | AF6: Bezares 80 | AG6: SI | AH6: Hyva 137-3 | AI6: guia 2647 Hyva | BB6: 3 GL | BC6: PLANTA | BD6: PLANTA
A7: Entregada | B7: 1346 | C7: ETP | D7: PORSCHE / QUILIN | E7: TOLVA | F7: TPI 14 M³ | G7: V.WAGEN | H7: 32360 | I7: 38808 | J7: 10490000 | K7: 1 | L7: 2 | M7: OK | N7: 44665 | O7: 1 | P7: OK | Q7: 1 | R7: OK | S7: 1.5 | T7: OK | U7: 2.5 | V7: OK | W7: 3 | X7: OK | Y7: 1 | Z7: OK | AA7: 1.5 | AB7: OK | AC7: 1 | AD7: INCORPORADO | AE7: SI | AF7: Bezares 80 | AG7: SI | AH7: Hyva 137-3 | AI7: guia 2647 Hyva | BB7: 3 GL | BC7: PLANTA | BD7: PLANTA
A8: Entregada | B8: 1337 | C8: CENTRO EQUIPOS | D8: OSERVIM | E8: TOLVA | F8: TRE 10 M³ A 12 M³ INOX | G8: V.WAGEN | H8: 32360 | I8: 38098 | J8: 14900000 | K8: 1 | L8: 5 | M8: OK | N8: 44685 | O8: 1 | P8: OK | Q8: - | R8: OK | S8: 2 | T8: OK | U8: 4.5 | V8: OK | W8: 4.5 | X8: OK | Y8: 1 | Z8: OK | AA8: 1 | AB8: OK | AC8: 1 | AD8: BEZARES | AE8: SI | AF8: Bezares 80 | AG8: SI | AH8: Hyva 157-4 | AI8: guia 2623 Hyva | BB8: 3 GL | BC8: PLANTA | BD8: PLANTA
A9: Entregada | B9: 1338 | C9: CENTRO EQUIPOS | D9: OSERVIM | E9: TOLVA | F9: TRE 10 M³ A 12 M³ INOX | G9: V.WAGEN | H9: 32360 | I9: 37971 | J9: 14900000 | K9: 1 | L9: 5 | M9: OK | N9: 44686 | O9: 1 | P9: OK | Q9: - | R9: OK | S9: 2 | T9: OK | U9: 3.5 | V9: OK | W9: 4.5 | X9: OK | Y9: 1 | Z9: OK | AA9: 1 | AB9: OK | AC9: 1 | AD9: BEZARES | AE9: SI | AF9: Bezares 80 | AG9: SI | AH9: Hyva 157-4 | AI9: guia 2623 Hyva | BB9: 3 GL | BC9: PLANTA | BD9: PLANTA
A10: Entregada | B10: 1363 | C10: ETP | D10: TRANSERIK | E10: TOLVA | F10: TPI 16 M³ A 17 M³ | G10: VOLVO | H10: VM 330 | I10: 180538 | J10: 12000000 | K10: 1 | L10: 3 | M10: OK | N10: 44670 | O10: 1 | P10: OK | Q10: - | R10: OK | S10: 2 | T10: OK | U10: 2 | V10: OK | W10: 2.5 | X10: OK | Y10: 1 | Z10: OK | AA10: 1 | AB10: OK | AC10: 1 | AD10: INCORPORADO | AE10: SI | AF10: Bezares 100 | AG10: SI | AH10: Hyva 157-4 | AI10: guia 2623 Hyva | BB10: 3 GL | BC10: PLANTA | BD10: PLANTA
A11: Entregada | B11: 1410 | C11: ETP | D11: TRANSERIK | E11: TOLVA | F11: TPI 16 M³ A 17 M³ | G11: VOLVO | H11: VM 330 | I11: 180539 | J11: 12000000 | K11: 1 | L11: 3 | M11: OK | N11: 44671 | O11: 1 | P11: OK | Q11: - | R11: OK | S11: 2 | T11: OK | U11: 3 | V11: OK | W11: 4 | X11: OK | Y11: 1.5 | Z11: OK | AA11: 1 | AB11: OK | AC11: 1 | AD11: INCORPORADO | AE11: SI | AF11: Bezares 100 | AG11: SI | AH11: Hyva 157-4 | AI11: guia 2623 Hyva | BB11: 3 GL | BC11: PLANTA | BD11: PLANTA
A12: Entregada | B12: 1352 | C12: ETP | D12: DIFOR | E12: TOLVA | F12: TPI 14 A 15 M³ | G12: V.WAGEN | H12: 32360 | I12: 11202 | J12: 10400000 | K12: 1 | L12: 4 | M12: OK | N12: 44680 | O12: 1 | P12: OK | Q12: - | R12: OK | S12: 2 | T12: OK | U12: 2.5 | V12: OK | W12: 2.5 | X12: OK | Y12: 1 | Z12: OK | AA12: 1 | AB12: OK | AC12: 1 | AD12: BEZARES | AE12: SI | AF12: Bezares 80 | AG12: SI | AH12: Hyva 137-3 | AI12: guia 20.04.2022 | BB12: NARANJO | BC12: PLANTA | BD12: PLANTA
A13: Entregada | B13: 1408 | C13: ETP | D13: CECOR | E13: TOLVA | F13: TPI 12 M³ A 14 M³ | G13: V.WAGEN | H13: 31360 | I13: 10654 | J13: 11000000 | K13: 1 | L13: 4 | M13: OK | N13: 44678 | O13: 1 | P13: OK | Q13: - | R13: OK | S13: 1.5 | T13: OK | U13: 2 | V13: OK | W13: 2.5 | X13: OK | Y13: 1 | Z13: OK | AA13: 1 | AB13: OK | AC13: 1 | AD13: BEZARES | AE13: SI | AF13: Bezares 80 | AG13: SI | AH13: Hyva 137-3 | AI13: guia 20.04.2022 | BB13: 3 GL | BC13: PLANTA | BD13: PLANTA
A14: Entregada | B14: 1409 | C14: ETP | D14: CECOR | E14: TOLVA | F14: TPI 12 M³ | G14: V.WAGEN | H14: 26280 | I14: 10964 | J14: 11000000 | K14: 1 | L14: 5 | M14: OK | N14: 44684 | O14: 1 | P14: OK | Q14: - | R14: OK | S14: 1.5 | T14: OK | U14: 2 | V14: OK | W14: 3 | X14: OK | Y14: 1 | Z14: OK | AA14: 1 | AB14: OK | AC14: 1 | AD14: FALTA CAMION | AF14: Bezares 80 | AG14: SI | AH14: BINOTTO 1494 | BB14: 3 GL | BC14: PLANTA | BD14: PLANTA
A15: Entregada | B15: 1376 | C15: CENTRO EQUIPOS | D15: DOCAL | E15: TOLVA | F15: TPI 14 M³ + PUERTA MINERA | G15: VOLVO | H15: VM 330 | I15: 181167 | J15: 13700000 | K15: 1 | L15: 4 | M15: OK | N15: 44677 | O15: 1 | P15: OK | Q15: - | R15: OK | S15: 2 | T15: OK | U15: 2 | V15: OK | W15: 2.5 | X15: OK | Y15: 1 | Z15: OK | AA15: 1 | AB15: OK | AC15: 1 | AD15: INCORPORADO | AE15: SI | AF15: Bezares 100 | AG15: SI | AH15: Hyva 137-3 | AI15: guia 2647 Hyva | BB15: 3 GL | BC15: PLANTA | BD15: PLANTA
A16: Entregada | B16: 1375 | C16: ETP | D16: EQUIPOS Y CAMIONES | E16: ALJIBE | F16: 20 M³ AGUA INDUSTRIAL | G16: V.WAGEN | H16: 31330 | I16: 47577 | J16: 19000000 | K16: 1 | L16: 3 | M16: OK | N16: 44671 | O16: 1 | P16: OK | Q16: - | R16: OK | S16: 1 | T16: OK | U16: 5.5 | V16: OK | W16: 4 | X16: OK | Y16: 1 | Z16: OK | AA16: 4 | AB16: OK | AC16: 2 | AD16: POR DEFINIR | AE16: SI | AF16: POR DEFINIR | AG16: SI | AK16: SI | AL16: SI | BB16: 4 GL. | BC16: PLanta | BD16: PLANTA
A17: Entregada | B17: 1202 | C17: ETP | D17: ALCANT. CONDOR | E17: ATMOSFERICO | F17: 20 + 3 | G17: VOLVO | H17: VM 330 | I17: 175514 | J17: 37990000 | K17: 1 | L17: 5 | M17: OK | N17: 44684 | O17: 1 | P17: OK | Q17: - | R17: OK | S17: - | T17: OK | U17: 4 | V17: OK | W17: 9.5 | X17: OK | Y17: 2.5 | Z17: OK | AA17: 19 | AB17: OK | AC17: 2.5
A18: Entregada | B18: 1424 | C18: ETP | D18: PORSCHE / TRANSP. LLAIMA | E18: TOLVA | F18: TOLVA TPI 15 M³ + KIT DE ARRASTRE + KIT HIDR. | G18: V.WAGEN | H18: 32360 | I18: 2784 | J18: 13950000 | K18: 1 | L18: 3 | M18: OK | N18: 44672 | O18: 1 | P18: OK | Q18: - | R18: OK | S18: 2 | T18: OK | U18: 2 | V18: OK | W18: 5.5 | X18: OK | Y18: 1 | Z18: OK | AA18: 1 | AB18: OK | AC18: 1 | AD18: BEZARES | AE18: SI | AF18: Bezares 80 | AG18: SI | AH18: Hyva 137-3 | AI18: guia 2647 Hyva | BB18: 3 GL | BD18: PLANTA
A19: Entregada | B19: 1377 | C19: CENTRO EQUIPOS | D19: DOCAL | E19: TOLVA | F19: TPI 14 M³ + PUERTA MINERA | G19: VOLVO | H19: VM 330 | I19: 181243 | J19: 13700000 | K19: 1 | L19: 4 | M19: OK | N19: 44678 | O19: 1 | P19: OK | Q19: - | R19: OK | S19: 2 | T19: OK | U19: 2.5 | V19: OK | W19: 3.5 | X19: OK | Y19: 1 | Z19: OK | AA19: 1 | AB19: OK | AC19: 1 | AD19: INCORPORADO | AE19: SI | AF19: Bezares 100 | AG19: SI | AH19: Hyva 137-3 | AI19: guia 2647 Hyva | BD19: PLANTA
A20: Entregada | B20: 1374 | C20: ETP | D20: VOLVO / ALVARO VILLEGA | E20: CARROCERIA MINERA | F20: 6.300x2.600x4x500 + PIÑAS | G20: VOLVO | H20: VM 330 | I20: 180880 | J20: 6500000 | K20: 1 | L20: 5 | M20: OK | N20: 44687 | O20: 1 | P20: OK | Q20: - | R20: OK | S20: 1.5 | T20: OK | U20: 2 | V20: OK | W20: 3.5 | X20: OK | Y20: 1 | Z20: - | AA20: - | AB20: OK | AC20: 1 | BB20: 2 GL | BC20: PLANTA | BD20: PLANTA
A21: Entregada | B21: 1246 | C21: CENTRO EQUIPOS | D21: BESALCO | E21: LUBRICADOR | F21: PLATAFORMA LUBRICADOR | G21: VOLVO | H21: VM 330 | I21: - | J21: 42500000 | K21: 1 | L21: 3 | M21: OK | N21: 44665 | O21: 1 | P21: OK | Q21: - | R21: OK | S21: 2 | T21: OK | U21: - | V21: OK | W21: - | X21: OK | Y21: - | Z21: OK | AA21: - | AB21: OK | AC21: - | BD21: PLANTA
P23: - | R23: - | T23: - | V23: - | X23: - | Z23: - | AB23: -
P24: - | R24: - | T24: - | V24: - | X24: - | Z24: - | AB24: -
P25: - | R25: - | T25: - | V25: - | X25: - | Z25: - | AB25: -
P26: - | R26: - | T26: - | V26: - | X26: - | Z26: - | AB26: -
P27: - | R27: - | T27: - | V27: - | X27: - | Z27: - | AB27: -
P28: - | R28: - | T28: - | V28: - | X28: - | Z28: - | AB28: -
P29: - | R29: - | T29: - | V29: - | X29: - | Z29: - | AB29: -
P30: - | R30: - | T30: - | V30: - | X30: - | Z30: - | AB30: -
P31: - | R31: - | T31: - | V31: - | X31: - | Z31: - | AB31: -
P32: - | R32: - | T32: - | V32: - | X32: - | Z32: - | AB32: -
P33: - | R33: - | T33: - | V33: - | X33: - | Z33: - | AB33: -
P34: - | R34: - | T34: - | V34: - | X34: - | Z34: - | AB34: -
C36: Mix de Producto | E36: Cliente Interno | H36: Total equipo Abril | I36: =SUM(O2:O34) -> 20 | J36: =SUM(J2:J34) -> 313810000 | K36: =SUM(P36:AB36) -> 1 | P36: 0.03 | R36: 0.1 | T36: 0.3 | V36: 0.3 | X36: 0.1 | Z36: 0.12 | AB36: 0.05
C37: ALJIBE | D37: =SUMIF($E$2:$E$34,C37,$O$2:$O$34) -> 1 | E37: ETP | F37: =SUMIF($C$2:$C$34,E37,$O$2:$O$38) -> 12 | M37: Equipo Fab. hasta
C38: ATMOSFERICO | D38: =SUMIF($E$2:$E$34,C38,$O$2:$O$34) -> 1 | E38: CENTRO EQUIPOS | F38: =SUMIF($C$2:$C$34,E38,$O$2:$O$38) -> 8 | H38: Equ. Fab. Y Facturado | J38: =SUMIF(K2:K34,K38,J2:J34) -> 313810000 | K38: 1 | N38: =SUMIF($K$2:$K$34,K38,$O$2:$O$34) -> 20
C39: CARROCERIA MINERA | D39: =SUMIF($E$2:$E$34,C39,$O$2:$O$34) -> 1 | H39: Equ. Facturado semanal | I39: 04/04 a 08/04 | J39: =SUMIF($L$2:$L$34,K39,$J$2:$J$34) -> 9800000 | K39: 1
C40: COMBUSTIBLE | D40: =SUMIF($E$2:$E$34,C40,$O$2:$O$34) -> 0 | E40: 1 | H40: Equ. Facturado semanal | I40: 11/04 a 15/04 | J40: =SUMIF($L$2:$L$34,K40,$J$2:$J$34) -> 31470000 | K40: 2
C41: COMBUSTIBLE AVIACION | D41: =SUMIF($E$2:$E$34,C41,$O$2:$O$34) -> 0 | H41: Equ. Facturado semanal | I41: 18/04 a 22/04 | J41: =SUMIF($L$2:$L$34,K41,$J$2:$J$34) -> 118950000 | K41: 3
C42: LUBRICADOR | D42: =SUMIF($E$2:$E$34,C42,$O$2:$O$34) -> 1 | H42: Equ. Facturado semanal | I42: 25/04 a 30/04 | J42: =SUMIF($L$2:$L$34,K42,$J$2:$J$34) -> 68300000 | K42: 4
...

Sheet MAY-22
A1: Prioridad | B1: OT | C1: Cliente Interno | D1: Cliente | E1: Equipo | F1: Modelo/Capacidad | G1: Camion | H1: Modelo | I1: Vin / Patente | J1: VALOR NETO | K1: % | L1: SM | N1: Fecha | P1: INGENIERIA | Q1: Dia | R1: CORTE Y PLEGADO | S1: Dia | T1: ARMADO | U1: Dia | V1: MONTAJE | W1: Dia | X1: PINTURA | Y1: Dia | Z1: HIDRAULICA | AA1: Dia | AB1: TERMINACIONES | AC1: Dia | AD1: PTO | AE1: STOCK | AF1: BBA H | AG1: STOCK | AH1: CILINDRO | AI1: STOCK | AJ1: DERIVADORA | AK1: MOTOR H | AL1: BBA CENT. | AM1: BBA VACIO | AN1: Bomba Comb. | AO1: Stock | AP1: Cuenta Litro | AQ1: Stock | AR1: Kit Combustible | AS1: Stock | AT1: Carrete | AU1: Stock | AV1: Manguera | AW1: Stock | AX1: Pistola | AY1: Stock | AZ1: Microfiltro | BA1: STOCK | BB1: Pintura | BC1: Stock | BD1: Acero
A2: Entregado | B2: 1314 | C2: CENTRO EQUIPOS | D2: VOLVO | E2: TOLVA | F2: TFR 25 M³ | G2: VOLVO | H2: FMX | I2: 917235 | J2: 19500000 | K2: 1 | L2: 4 | M2: OK | N2: 44707 | O2: 1 | P2: OK | Q2: - | R2: OK | S2: 2 | T2: OK | U2: 5 | V2: OK | W2: 5.5 | X2: OK | Y2: 1.5 | Z2: OK | AA2: 1.5 | AB2: OK | AC2: 1.5 | AD2: INCORPORADO | AE2: SI | AF2: Bezares 100 | AG2: SI | AH2: Hyva 169-4 | AI2: SI | BB2: 4 GL | BC2: PLANTA | BD2: PLANTA
A3: Entregado | B3: 1315 | C3: CENTRO EQUIPOS | D3: VOLVO | E3: TOLVA | F3: TFR 25 M³ | G3: VOLVO | H3: FMX | I3: 917234 | J3: 19500000 | K3: 1 | L3: 4 | M3: OK | N3: 44708 | O3: 1 | P3: OK | Q3: - | R3: OK | S3: 2 | T3: OK | U3: 4 | V3: OK | W3: 6.5 | X3: OK | Y3: 1.5 | Z3: OK | AA3: 1.5 | AB3: OK | AC3: 1.5 | AD3: INCORPORADO | AE3: SI | AF3: Bezares 100 | AG3: SI | AH3: Hyva 169-4 | AI3: SI | BB3: 4 GL | BC3: PLANTA | BD3: PLANTA
A4: Entregado | B4: 1370 | C4: CENTRO EQUIPOS | D4: VOLVO | E4: TOLVA | F4: TPI 14 A 15 M³ | G4: VOLVO | H4: VM 330 | I4: 181342 | J4: 14700000 | K4: 1 | L4: 2 | M4: OK | N4: 44692 | O4: 1 | P4: OK | Q4: - | R4: OK | S4: 1 | T4: OK | U4: 3 | V4: OK | W4: 2.5 | X4: OK | Y4: 1 | Z4: OK | AA4: 1 | AB4: OK | AC4: 1 | AD4: INCORPORADO | AE4: SI | AF4: Bezares 100 | AG4: SI | AH4: Hyva 137-3 | AI4: SI | BB4: 3 GL | BC4: PLANTA | BD4: PLANTA
A5: Entregado | B5: 1428 | C5: ETP | D5: KAUFMANN | E5: TOLVA | F5: TRE 12 A 14 M³ | G5: M.BENZ | H5: 3131 | I5: 246323 | J5: 12000000 | K5: 1 | L5: 5 | M5: OK | N5: 44711 | O5: 1 | P5: OK | Q5: - | R5: OK | S5: 1.5 | T5: OK | U5: 2 | V5: OK | W5: 4 | X5: OK | Y5: 1 | Z5: OK | AA5: 1.5 | AB5: OK | AC5: 1 | AD5: FALTA CAMION | AF5: Bezares 80 | AG5: SI | AH5: Hyva 137-4 | AI5: SI | BB5: 3 GL | BC5: PLANTA | BD5: PLANTA
A6: Entregado | B6: 1316 | C6: CENTRO EQUIPOS | D6: VOLVO | E6: TOLVA | F6: TFR 25 M³ | G6: VOLVO | H6: FMX | I6: 917241 | J6: 25300000 | K6: 1 | L6: 5 | M6: OK | N6: 44715 | O6: 1 | P6: OK | Q6: - | R6: OK | S6: 2 | T6: OK | U6: 4.5 | V6: OK | W6: 6 | X6: OK | Y6: 1 | Z6: OK | AA6: 2 | AB6: OK | AC6: 1.5 | AD6: INCORPORADO | AE6: SI | AF6: Bezares 100 | AG6: SI | AH6: Hyva 157-4 | AI6: SI | BB6: 4 GL | BC6: PLANTA | BD6: PLANTA
A7: Entregado | B7: 1281 | C7: CENTRO EQUIPOS | D7: SCANIA | E7: TOLVA | F7: TFR 25 M³ | G7: SCANIA | H7: G500B | I7: 4011931 | J7: 31330000 | K7: 1 | L7: 5 | M7: OK | N7: 44716 | O7: 1 | P7: OK | Q7: - | R7: OK | S7: 1.5 | T7: OK | U7: 3.5 | V7: OK | W7: 5 | X7: OK | Y7: 1 | Z7: OK | AA7: 2 | AB7: OK | AC7: 1 | AD7: FALTA CAMION | AF7: Bezares 80 | AG7: SI | AH7: Hyva 157-4 | AI7: SI | BB7: 4 GL | BC7: PLANTA | BD7: PLANTA
A8: Entregado | B8: 1427 | C8: ETP | D8: PORSCHE | E8: TOLVA | F8: TPI 15 M³ + GANCHO DE TIRO | G8: V.WAGEN | H8: 32360 | I8: 2934 | J8: 14130000 | K8: 1 | L8: 2 | M8: OK | N8: 44693 | O8: 1 | P8: OK | Q8: - | R8: OK | S8: 1 | T8: OK | U8: 2.5 | V8: OK | W8: 3 | X8: OK | Y8: 1 | Z8: OK | AA8: 1 | AB8: OK | AC8: 1.5 | AD8: BEZARES | AE8: SI | AF8: Bezares 80 | AG8: SI | AH8: Hyva 137-3 | AI8: SI | BB8: 3 GL | BC8: PLANTA | BD8: PLANTA
A9: Entregado | B9: 1353 | C9: ETP | D9: DIFOR | E9: TOLVA | F9: TPI 14 A 15 M³ | G9: V.WAGEN | H9: 32360 | I9: 11237 | J9: 14700000 | K9: 1 | L9: 2 | M9: OK | N9: 44694 | O9: 1 | P9: OK | Q9: - | R9: OK | S9: 1 | T9: OK | U9: 4 | V9: OK | W9: 2.5 | X9: OK | Y9: 1 | Z9: OK | AA9: 1.5 | AB9: OK | AC9: 1 | AD9: BEZARES | AE9: SI | AF9: Bezares 80 | AG9: SI | AH9: Hyva 137-3 | AI9: SI | BB9: 3 GL | BC9: PLANTA | BD9: PLANTA
A10: Entregado | B10: 1378 | C10: ETP | D10: MAURICIO VALDIVIA | E10: ALJIBE | F10: 20 M³ INOX | G10: VOLVO | H10: VM 330 | I10: 180535 | J10: 26500000 | K10: 1 | L10: 1 | M10: OK | N10: 44687 | O10: 1 | P10: OK | Q10: - | R10: OK | S10: 1 | T10: OK | U10: 6.5 | V10: OK | W10: 5.5 | X10: OK | Y10: - | Z10: OK | AA10: 5 | AB10: OK | AC10: 1 | AD10: INCORPORADO | AE10: SI | AF10: POR DEFINIR | AG10: SI | AH10: Hyva 137-3 | AI10: SI | BB10: 4 GL | BC10: PLANTA | BD10: PLANTA
A11: Entregado | B11: 1270 | C11: CENTRO EQUIPOS | D11: AUTOSUMMIT / T VABA | E11: ALJIBE | F11: 20 M³ INOX | G11: V.WAGEN | H11: 32360 | I11: 3081 | J11: 27550000 | K11: 1 | L11: 2 | M11: OK | N11: 44694 | O11: 1 | P11: OK | Q11: - | R11: OK | S11: 1.5 | T11: OK | U11: 6 | V11: OK | W11: 4.5 | X11: OK | Y11: 1 | Z11: OK | AA11: 4 | AB11: OK | AC11: 1.5 | AD11: BEZARES | AE11: SI | AF11: POR DEFINIR | AG11: SI | AH11: --------------- | BB11: 4 GL | BC11: PLANTA | BD11: PLANTA
A12: Entregado | B12: 1262 | C12: CENTRO EQUIPOS | D12: LAURO RIOS | E12: CARROCERIA MINERA | F12: 6.300x2.600x4x500 + PIÑAS | G12: V.WAGEN | H12: 32360 | I12: 32309 | J12: 6600000 | K12: 1 | L12: 2 | M12: OK | N12: 44693 | O12: 1 | P12: OK | Q12: - | R12: OK | S12: 1 | T12: OK | U12: 2 | V12: OK | W12: 3 | X12: OK | Y12: 1 | Z12: OK | AA12: - | AB12: OK | AC12: 1 | AD12: SIN T/F | AE12: -------------- | AF12: -------------- | AG12: -------------- | AH12: --------------- | BB12: 2 GL | BC12: PLANTA | BD12: PLANTA
A13: Entregado | B13: 973 | C13: CENTRO EQUIPOS | D13: MAESTRANZA ALEMANIA | E13: COMBUSTIBLE | F13: 20 M³ AF | G13: M.BENZ | H13: 3342 | I13: 531846 | J13: 64000000 | K13: 1 | L13: 5 | M13: OK | N13: 44755 | O13: 1 | P13: OK | Q13: - | R13: OK | S13: 1 | T13: OK | U13: 8.5 | V13: OK | W13: 15 | X13: OK | Y13: 3 | Z13: OK | AA13: - | AB13: OK | AC13: - | AD13: BEZARES | AE13: SI | AF13: POR DEFINIR | AG13: SI | AH13: --------------- | AN13: 4" | AO13: PLANTA | AP13: m25 - m10 | AQ13: PLANTA | AR13: valvulas | AS13: PLANTA | AT13: 1"-11/2" - 21/2" | AU13: PLANTA | AV13: 1" - 11/2" - 21/2" | AW13: PLANTA | AX13: 1" - 11/2" . - VR 300 | AY13: SOLICITADA | AZ13: 300 glp | BA13: SOLICITADA | BB13: 4 GL | BC13: PLANTA | BD13: PLANTA
A14: Entregado | B14: 1137 | C14: CENTRO EQUIPOS | D14: OSERVIM | E14: ALJIBE | F14: 20 M³ INOX | G14: V.WAGEN | H14: 32360 | I14: 38062 | J14: 16200000 | K14: 1 | L14: 4 | M14: OK | N14: 44708 | O14: 1 | P14: OK | Q14: - | R14: OK | S14: 1 | T14: OK | U14: 5 | V14: OK | W14: 4 | X14: OK | Y14: 1 | Z14: OK | AA14: 4 | AB14: OK | AC14: 3 | AF14: POR DEFINIR | AG14: SI | AH14: --------------- | BB14: 4 GL | BC14: PLANTA | BD14: PLANTA
A15: Entregado | B15: 1326 | C15: CENTRO EQUIPOS | D15: SALFA | E15: COMBUSTIBLE | F15: 3 M³ MINERO | G15: CHEVROLET | H15: NPR 816 | I15: 7101292 | J15: 22000000 | K15: 1 | L15: 5 | M15: OK | N15: 44729 | O15: 1 | P15: OK | Q15: - | R15: OK | S15: 1 | T15: OK | U15: 6 | V15: OK | W15: 6.5 | X15: OK | Y15: - | Z15: OK | AA15: 13 | AB15: OK | AC15: 2 | AD15: FALTA CAMION | AF15: POR DEFINIR | AG15: SI | AH15: --------------- | AN15: BLACKMER 21/2 | AO15: SOLICITADO | AP15: M7 LIQUID CONTROL | AQ15: SOLICITADO | AR15: VALVULAS | AS15: PLANTA | AT15: 11/2 - 1" IPT | AU15: PLANTA | AV15: 15 MT 1" 15 MTS 11/2 | AW15: SOLICITADO | AX15: FLOMAX 11/2 - OPW 1" | AY15: SOLICITADO | AZ15: NO | BA15: ---------- | BB15: 2 GL | BC15: DEFINIR | BD15: PLANTA
A16: Entregado | B16: 1265 | C16: CENTRO EQUIPOS | D16: BESALCO | E16: COMBUSTIBLE | F16: 15 M³ | G16: INTERNATIONAL | H16: 7600 | I16: GKPH-94 | J16: 22400000 | K16: 1 | L16: 1 | M16: OK | N16: 44719 | O16: 1 | P16: OK | Q16: - | R16: OK | S16: 1.5 | T16: OK | U16: 8 | V16: OK | W16: 10 | X16: OK | Y16: 2 | Z16: OK | AA16: 15 | AB16: OK | AC16: 5 | AD16: INCORPORADO | AE16: SI | AF16: POR DEFINIR | AG16: SI | AH16: --------------- | AN16: IPT 2" | AO16: PLANTA | AP16: M5 | AQ16: SOLICITADO | AR16: valvulas | AS16: PLANTA | AT16: 9039 PTO | AU16: SI | AV16: 11/2 X 15 MTS | AW16: SOLICITADO | AX16: OPW 11/2 | AY16: SOLICITADO | AZ16: SEPARADOR DE AGUA | BA16: SOLICITADO | BB16: GRIS | BC16: PLANTA | BD16: PLANTA
A17: Entregado | B17: 1369 | C17: ETP | D17: SACYR | E17: ATMOSFERICO | F17: 18 M³ + 2M³ | G17: V.WAGEN | H17: 32360 | I17: 21096 | J17: 42950000 | K17: 1 | L17: 5 | M17: OK | N17: 44749 | O17: 1 | P17: OK | Q17: - | R17: OK | S17: 1.5 | T17: OK | U17: 10 | V17: OK | W17: 7.5 | X17: OK | Y17: - | Z17: OK | AA17: - | AB17: OK | AC17: - | AD17: BEZARES | AE17: SI | AF17: POR DEFINIR | AG17: SI | AH17: --------------- | BB17: 4 GL | BC17: PLANTA | BD17: PLANTA
A18: Entregado | B18: 1327 | C18: CENTRO EQUIPOS | D18: CARMONA | E18: ALJIBE | F18: 20 M³ | G18: V.WAGEN | H18: 32360 | I18: 44024 | J18: 22500000 | K18: 1 | L18: 5 | M18: OK | N18: 44713 | O18: 1 | P18: OK | Q18: - | R18: OK | S18: 1 | T18: OK | U18: 4.5 | V18: OK | W18: 4.5 | X18: OK | Y18: 2 | Z18: OK | AA18: 6 | AB18: OK | AC18: 3 | BB18: 4 GL | BC18: PLANTA | BD18: PLANTA
A19: Entregado | B19: 1354 | C19: ETP | D19: DIFOR | E19: TOLVA | F19: TPI 14 A 15 M³ | G19: V.WAGEN | H19: 32360 | I19: 11601 | J19: 14700000 | K19: 1 | L19: 4 | M19: OK | N19: 44706 | O19: 1 | P19: OK | Q19: - | R19: OK | S19: 1.5 | T19: OK | U19: 4 | V19: OK | W19: 3 | X19: OK | Y19: 1 | Z19: OK | AA19: 1 | AB19: OK | AC19: 1 | BB19: 3 GL | BC19: PLANTA | BD19: PLANTA
A20: Entregado | B20: 1432 | C20: ETP | D20: EQUIP. Y CAM. / TRANSP. ARANCIBIA | E20: CARROCERIA MINERA | F20: 4.700x2.300x500 | G20: HINO | H20: XZU 616 | I20: 6635 | J20: 3570000 | K20: 1 | L20: 5 | M20: OK | N20: 44713 | O20: 1 | P20: OK | Q20: - | R20: OK | S20: 1 | T20: OK | U20: 1.5 | V20: OK | W20: 1.5 | X20: OK | Y20: 1 | Z20: OK | AA20: - | AB20: OK | AC20: 1 | BB20: 2 GL | BC20: PLANTA | BD20: PLANTA
A21: Entregado | B21: 1433 | C21: ETP | D21: EQUIP. Y CAM. / TRANSP. ARANCIBIA | E21: CARROCERIA MINERA | F21: 6.300x2.400x500 | G21: HINO | H21: FC 1118 | I21: 11450 | J21: 4990000 | K21: 1 | L21: 5 | M21: OK | N21: 44715 | O21: 1 | P21: OK | Q21: - | R21: OK | S21: 1 | T21: OK | U21: 2 | V21: OK | W21: 2 | X21: OK | Y21: 1 | Z21: OK | AA21: - | AB21: OK | AC21: 1 | BB21: 2 GL | BC21: PLANTA | BD21: PLANTA
P22: - | Q22: - | R22: - | S22: - | T22: - | U22: - | V22: - | W22: - | X22: - | Y22: - | Z22: - | AA22: - | AB22: - | AC22: -
P23: - | Q23: - | R23: - | S23: - | T23: - | U23: - | V23: - | W23: - | X23: - | Y23: - | Z23: - | AA23: - | AB23: - | AC23: -
P24: - | Q24: - | R24: - | S24: - | T24: - | U24: - | V24: - | W24: - | X24: - | Y24: - | Z24: - | AA24: - | AB24: - | AC24: -
P25: - | Q25: - | R25: - | S25: - | T25: - | U25: - | V25: - | W25: - | X25: - | Y25: - | Z25: - | AA25: - | AB25: - | AC25: -
P26: - | Q26: - | R26: - | S26: - | T26: - | U26: - | V26: - | W26: - | X26: - | Y26: - | Z26: - | AA26: - | AB26: - | AC26: -
P27: - | Q27: - | R27: - | S27: - | T27: - | U27: - | V27: - | W27: - | X27: - | Y27: - | Z27: - | AA27: - | AB27: - | AC27: -
P28: - | Q28: - | R28: - | S28: - | T28: - | U28: - | V28: - | W28: - | X28: - | Y28: - | Z28: - | AA28: - | AB28: - | AC28: -
P29: - | Q29: - | R29: - | S29: - | T29: - | U29: - | V29: - | W29: - | X29: - | Y29: - | Z29: - | AA29: - | AB29: - | AC29: -
P30: - | Q30: - | R30: - | S30: - | T30: - | U30: - | V30: - | W30: - | X30: - | Y30: - | Z30: - | AA30: - | AB30: - | AC30: -
P31: - | Q31: - | R31: - | S31: - | T31: - | U31: - | V31: - | W31: - | X31: - | Y31: - | Z31: - | AA31: - | AB31: - | AC31: -
P32: - | Q32: - | R32: - | S32: - | T32: - | U32: - | V32: - | W32: - | X32: - | Y32: - | Z32: - | AA32: - | AB32: - | AC32: -
P33: - | Q33: - | R33: - | S33: - | T33: - | U33: - | V33: - | W33: - | X33: - | Y33: - | Z33: - | AA33: - | AB33: - | AC33: -
... P40: - | Q40: - | R40: - | S40: - | T40: - | U40: - | V40: - | W40: - | X40: - | Y40: - | Z40: - | AA40: - | AB40: - | AC40: -
C42: Mix de Producto | E42: Cliente Interno | H42: Total equipo Mayo | I42: =SUM(O2:O40) -> 20 | J42: =SUM(J2:J40) -> 425120000 | K42: =SUM(P42:AB42) -> 1 | P42: 0.03 | R42: 0.1 | T42: 0.3 | V42: 0.3 | X42: 0.1 | Z42: 0.12 | AB42: 0.05
C43: ALJIBE | D43: =SUMIF($E$2:$E$41,C43,$O$2:$O$41) -> 4 | E43: ETP | F43: =SUMIF($C$2:$C$41,E43,$O$2:$O$41) -> 8 | M43: Equipo Fab hasta
C44: ATMOSFERICO | D44: =SUMIF($E$2:$E$41,C44,$O$2:$O$41) -> 1 | E44: CENTRO EQUIPOS | F44: =SUMIF($C$2:$C$41,E44,$O$2:$O$41) -> 12 | H44: Equ. Fab. Y Facturado | J44: =SUMIF(K2:K40,K44,J2:J40) -> 425120000 | K44: 1 | N44: =SUMIF($K$2:$K$41,K44,$O$2:$O$41) -> 20
C45: CARROCERIA MINERA | D45: =SUMIF($E$2:$E$41,C45,$O$2:$O$41) -> 3 | H45: Equ. Facturado semanal | I45: 02/05 a 07/05 | J45: =SUMIF($L$2:$L$40,K45,$J$2:$J$40) -> 48900000 | K45: 1
C46: COMBUSTIBLE | D46: =SUMIF($E$2:$E$41,C46,$O$2:$O$41) -> 3 | H46: Equ. Facturado semanal | I46: 09/05 a 14/05 | J46: =SUMIF($L$2:$L$40,K46,$J$2:$J$40) -> 77680000 | K46: 2
C47: COMBUSTIBLE AVIACION | D47: =SUMIF($E$2:$E$41,C47,$O$2:$O$41) -> 0 | H47: Equ. Facturado semanal | I47: 16/05 a 21/05 | J47: =SUMIF($L$2:$L$40,K47,$J$2:$J$40) -> 0 | K47: 3
...

Sheet JUN-22
A1: Prioridad | B1: OT | C1: Cliente Interno | D1: Cliente | E1: Equipo | F1: Modelo/Capacidad | G1: Camion | H1: Modelo | I1: Vin / Patente | J1: VALOR NETO | K1: % | L1: SM | N1: Fecha | P1: INGENIERIA | Q1: Dia | R1: CORTE Y PLEGADO | S1: Dia | T1: ARMADO | U1: Dia | V1: MONTAJE | W1: Dia | X1: PINTURA | Y1: Dia | Z1: HIDRAULICA | AA1: Dia | AB1: TERMINACIONES | AC1: Dia | AD1: PTO | AE1: STOCK | AF1: BBA H | AG1: STOCK | AH1: CILINDRO | AI1: STOCK | AJ1: DERIVADORA | AK1: MOTOR H | AL1: BBA CENT. | AM1: BBA VACIO | AN1: Bomba Comb. | AO1: Stock | AP1: Cuenta Litro | AQ1: Stock | AR1: Kit Combustible | AS1: Stock | AT1: Carrete | AU1: Stock | AV1: Manguera | AW1: Stock | AX1: Pistola | AY1: Stock | AZ1: Microfiltro | BA1: STOCK | BB1: Pintura | BC1: Stock | BD1: Acero
A2: Entregado | B2: 1282 | C2: CENTRO EQUIPOS | D2: SCANIA | E2: TOLVA | F2: TFR 25 M³ | G2: SCANIA | H2: G500B | I2: 4011953 | J2: 31330000 | K2: 1 | L2: 3 | M2: OK | N2: 44729 | O2: 1 | P2: OK | Q2: - | R2: OK | S2: 1.5 | T2: OK | U2: 7 | V2: OK | W2: 4 | X2: OK | Y2: 1.5 | Z2: OK | AA2: 1.5 | AB2: OK | AC2: 1 | AD2: INCORPORADO | AF2: Bezares 100 | AG2: SI | AH2: Hyva 179-5 | AI2: SI | BB2: 4 GL | BC2: PLANTA | BD2: PLANTA
A3: Entregado | B3: 1426 | C3: ETP | D3: MUNI. DE PUNITAQUI | E3: TOLVA | F3: TRE 10 M³ | G3: V.WAGEN | H3: 17330 | I3: 41313 | J3: 11000000 | K3: 1 | L3: 2 | M3: OK | N3: 44718 | O3: 1 | P3: OK | Q3: - | R3: OK | S3: 1 | T3: OK | U3: 3 | V3: OK | W3: 3.5 | X3: OK | Y3: 1 | Z3: OK | AA3: 1.5 | AB3: OK | AC3: 1.5 | AD3: FALTA CAMION | AF3: Bezares 80 | AG3: SI | AH3: Hyva 137-3 | AI3: SI | BB3: 3 GL | BC3: PLANTA | BD3: PLANTA
A4: Entregado | B4: 1430 | C4: ETP | D4: CECOR | E4: TOLVA | F4: TPI 14 M³ + KIT ARRASTRE | G4: V.WAGEN | H4: 31330 | I4: 17190 | J4: 11000000 | K4: 1 | L4: 2 | M4: OK | N4: 44722 | O4: 1 | P4: OK | Q4: - | R4: OK | S4: 1.5 | T4: OK | U4: 3.5 | V4: OK | W4: 3.5 | X4: OK | Y4: 1 | Z4: OK | AA4: 1.5 | AB4: OK | AC4: 1 | AD4: BEZARES | AE4: SI | AF4: Bezares 80 | AG4: SI | AH4: Hyva 137-3 | AI4: SI | BB4: 3 GL | BC4: PLANTA | BD4: PLANTA
A5: Entregado | B5: 1436 | C5: ETP | D5: PATAGON | E5: TOLVA | F5: 3,5 M³ | G5: DIECI | H5: L4700 | I5: L4700 | J5: 7000000 | K5: 1 | L5: 5 | M5: OK | N5: 44753 | O5: 1 | P5: OK | Q5: - | R5: OK | S5: 1.5 | T5: OK | U5: 1.5 | V5: OK | W5: 4.5 | X5: OK | Y5: 1 | Z5: OK | AA5: 2 | AB5: OK | AC5: - | AD5: L4700 | AE5: P.DEFINIR | AF5: POR DEFINIR | AH5: HIDROSIR 120-5 | AI5: SI | BB5: 2 GL | BC5: PLANTA | BD5: PLANTA
A6: Entregado | B6: 1429 | C6: ETP | D6: CECOR | E6: TOLVA | F6: TPI 12 A 14 M³ | G6: V.WAGEN | H6: 31330 | I6: 16468 | J6: 11000000 | K6: 1 | L6: 5 | M6: OK | N6: 44742 | O6: 1 | P6: OK | Q6: - | R6: OK | S6: 1.5 | T6: OK | U6: 2.5 | V6: OK | W6: 2 | X6: OK | Y6: 1 | Z6: OK | AA6: 1.5 | AB6: OK | AC6: 1.5 | AD6: FALTA CAMION | AE6: P.DEFINIR | AF6: POR DEFINIR | AH6: Hyva 137-3 | AI6: SI | BB6: 3 GL | BC6: PLANTA | BD6: PLANTA
A7: Entregado | B7: 1431 | C7: ETP | D7: AUTOSUMMIT / ZION SERVICES | E7: ATMOSFERICO | F7: 2.5 M³ + 1 M³ | G7: HINO | H7: XZU 616 | I7: 6581 | J7: 25739600 | K7: 1 | L7: 5 | M7: OK | N7: 44742 | O7: 1 | P7: OK | Q7: - | R7: OK | S7: 1 | T7: OK | U7: 3.5 | V7: OK | W7: 4 | X7: OK | Y7: 1.5 | Z7: OK | AA7: 12.5 | AB7: OK | AC7: - | BB7: 2 GL | BC7: PLANTA | BD7: PLANTA
A8: Entregado | B8: 1425 | C8: ETP | D8: HIDROMASS | E8: ATMOSFERICO | F8: 2.5 M³ + 1 M³ | G8: HINO | H8: XZU 616 | I8: 6458 | J8: 16975000 | K8: 1 | L8: 5 | M8: OK | N8: 44742 | O8: 1 | P8: OK | Q8: - | R8: OK | S8: 1 | T8: OK | U8: 3 | V8: OK | W8: 6.5 | X8: OK | Y8: 1.5 | Z8: OK | AA8: 7.5 | AB8: OK | AC8: - | BB8: 2 GL | BC8: PLANTA | BD8: PLANTA
A9: Entregado | B9: 1178 | C9: CENTRO EQUIPOS | D9: SALFA | E9: COMBUSTIBLE | F9: 5 M³ | G9: CHEVROLET | H9: NPR 816 | I9: 7101138 | J9: 17200000 | K9: 1 | L9: 3 | M9: OK | N9: 44727 | O9: 1 | P9: OK | Q9: - | R9: OK | S9: 1 | T9: OK | U9: 6.5 | V9: OK | W9: 7 | X9: OK | Y9: 1.5 | Z9: OK | AA9: 8 | AB9: OK | AC9: 2 | AD9: BEZARES | AE9: SI | AF9: ------------ | AG9: SI | AH9: --------------- | AN9: IPT 2" | AO9: PLANTA | AP9: IPT | AQ9: PLANTA | AR9: valvulas | AS9: PLANTA | AT9: 1" IPT | AU9: PLANTA | AV9: 15MTS 1" | AW9: SOLICITADO | AX9: 1" OPW | AY9: SOLICITADO | AZ9: --------- | BA9: ---------- | BB9: 2 GL | BC9: PLANTA | BD9: PLANTA
A10: Entregado | B10: 1434 | C10: ETP | D10: AUTOSUMMIT | E10: ALJIBE | F10: 12 M³ | G10: V.WAGEN | H10: 17230 | I10: 15906 | J10: 19300000 | K10: 1 | L10: 5 | M10: OK | N10: 44746 | O10: 1 | P10: OK | Q10: - | R10: OK | S10: 1 | T10: OK | U10: 5 | V10: OK | W10: 4.5 | X10: OK | Y10: 1 | Z10: OK | AA10: 6 | AB10: OK | AC10: 3 | BB10: 3GL | BC10: PLANTA | BD10: PLANTA
A11: Entregado | B11: 1238 | C11: CENTRO EQUIPOS | D11: SALFA | E11: ALJIBE | F11: 30 M³ | G11: RENAULT | H11: K-480 | I11: 1099 | J11: 21500000 | K11: 1 | L11: 2 | M11: OK | N11: 44718 | O11: 1 | P11: OK | Q11: - | R11: OK | S11: 2 | T11: OK | U11: 7 | V11: OK | W11: 5.5 | X11: OK | Y11: 1 | Z11: OK | AA11: 4 | AB11: OK | AC11: 3 | AD11: INCORPORADO | AE11: si | AF11: POR DEFINIR | AG11: SI | AH11: --------------- | BB11: 4 GL | BC11: PLANTA | BD11: PLANTA
A12: Entregado | B12: 1322 | C12: CENTRO EQUIPOS | D12: CECOR | E12: COMBUSTIBLE | F12: 5 M³ | G12: HINO | H12: FC 1118 | I12: 112950 | J12: 17300000 | K12: 1 | L12: 5 | M12: OK | N12: 44755 | O12: 1 | P12: OK | Q12: - | R12: OK | S12: 1.5 | T12: OK | U12: 5 | V12: OK | W12: 6.5 | X12: OK | Y12: 1 | Z12: OK | AA12: - | AB12: OK | AC12: - | BB12: 3 GL | BC12: PLANTA | BD12: PLANTA
A13: Entregado | B13: 1269 | C13: CENTRO EQUIPOS | D13: VOLVO / LAURO RIOS | E13: ALJIBE | F13: 20 M³ | G13: VOLVO | H13: VM 330 | I13: 181344 | J13: 21000000 | K13: 1 | L13: 4 | M13: OK | N13: 44735 | O13: 1 | P13: OK | Q13: - | R13: OK | S13: 1.5 | T13: OK | U13: 5.5 | V13: OK | W13: 4.5 | X13: OK | Y13: 2 | Z13: OK | AA13: 5.5 | AB13: OK | AC13: 2 | AD13: INCORPORADO | AE13: SI | AF13: POR DEFINIR | AG13: SI | BB13: 4 GL | BC13: PLANTA | BD13: PLANTA
A14: Entregado | B14: 1155 | C14: CENTRO EQUIPOS | D14: MIES | E14: LUBRICADOR | F14: FURGON CERRADO | G14: M.BENZ | H14: 3342 | I14: 535861 | K14: 1 | L14: 5 | M14: OK | N14: 44742 | O14: 1 | P14: OK | Q14: - | R14: OK | S14: 1 | T14: OK | U14: - | V14: OK | W14: - | X14: OK | Y14: - | Z14: OK | AA14: - | AB14: OK | AC14: 6.5 | BB14: 7 GL | BC14: PLANTA | BD14: PLANTA
A15: Entregado | B15: 1393 | C15: ETP | D15: PORSCHE MAN | E15: LUBRICADOR | F15: CERRADO | G15: MAN | H15: TGS 18.320 | I15: 77837 | J15: 49200000 | K15: 1 | L15: 3 | M15: OK | N15: 44727 | O15: 1 | P15: OK | Q15: - | R15: OK | S15: 1 | T15: OK | U15: 23 | V15: OK | W15: - | X15: OK | Y15: - | Z15: OK | AA15: - | AB15: OK | AC15: 5.5 | AD15: FALTA CAMION | AF15: POR DEFINIR | AG15: SI | AH15: --------------- | AN15: 4" | AO15: no | AP15: m25 - m10 | AQ15: no | AR15: valvulas | AT15: 1"-11/2" - 21/2" | AU15: no | AV15: 1" - 11/2" - 21/2" | AW15: no | AX15: 1" - 11/2" . - VR 300 | AZ15: 300 glp | BA15: no | BB15: 6 GL | BC15: PLANTA | BD15: PLANTA
A16: Entregado | B16: 1403 | C16: ETP | D16: PORSCHE MAN | E16: LUBRICADOR | F16: CERRADO | G16: MAN | H16: TGS 18.320 | I16: 891520 | J16: 49200000 | K16: 1 | L16: 5 | M16: OK | N16: 44748 | O16: 1 | P16: OK | Q16: - | R16: OK | S16: 2 | T16: OK | U16: 11 | V16: OK | W16: 7.5 | X16: OK | Y16: 2 | Z16: OK | AA16: 9 | AB16: OK | AC16: 2.5 | BB16: 6 GL | BC16: PLANTA | BD16: PLANTA
A17: Entregado | B17: 1266 | C17: CENTRO EQUIPOS | D17: CARMONA | E17: TOLVA | F17: TPI 14 M³ | G17: V.WAGEN | H17: 31330 | I17: 16455 | J17: 16250000 | K17: 1 | L17: 4 | M17: OK | N17: 44736 | O17: 1 | P17: OK | Q17: - | R17: OK | S17: 2 | T17: OK | U17: 3.5 | V17: OK | W17: 2.5 | X17: OK | Y17: 1.5 | Z17: OK | AA17: 1.5 | AB17: OK | AC17: 1.5 | AH17: Hyva 137-3 | AI17: SI | BB17: 3 GL | BC17: PLANTA | BD17: PLANTA
A18: Entregado | B18: 1298 | C18: CENTRO EQUIPOS | D18: CARMONA | E18: TOLVA | F18: 14-15 M³ | G18: V.WAGEN | H18: 32360 | I18: 11609 | J18: 18220000 | K18: 1 | L18: 4 | M18: OK | N18: 44735 | O18: 1 | P18: OK | Q18: - | R18: OK | S18: 2 | T18: OK | U18: 4 | V18: OK | W18: 2.5 | X18: OK | Y18: 1 | Z18: OK | AA18: 1.5 | AB18: OK | AC18: - | AH18: Hyva 137-3 | AI18: SI | BB18: 3 GL | BC18: PLANTA | BD18: PLANTA
A19: Entregado | B19: 1439 | C19: ETP | D19: CECOR | E19: TOLVA | F19: TPI 14 M³ | G19: V.WAGEN | H19: 31330 | I19: 17202 | J19: 11000000 | K19: 1 | L19: 3 | M19: OK | N19: 44726 | O19: 1 | P19: OK | Q19: - | R19: OK | S19: 1.5 | T19: OK | U19: 2.5 | V19: OK | W19: 4 | X19: OK | Y19: 1 | Z19: OK | AA19: 1.5 | AB19: OK | AC19: 1.5 | AH19: Hyva 137-3 | AI19: SI | BB19: 3 GL | BC19: PLANTA | BD19: PLANTA
A20: Entregado | B20: 1236 | C20: ETP | D20: PORSCHE / AGRICOLA DON ALEJO | E20: TOLVA | F20: TPI 14 M³ | G20: V.WAGEN | H20: 32360 | I20: 11616 | J20: 14700000 | K20: 1 | L20: 3 | M20: OK | N20: 44727 | O20: 1 | P20: OK | Q20: - | R20: OK | S20: 1.5 | T20: OK | U20: 2 | V20: OK | W20: 2.5 | X20: OK | Y20: 1 | Z20: OK | AA20: 1.5 | AB20: OK | AC20: 1.5 | AH20: Hyva 137-3 | AI20: SI | BB20: 3 GL | BC20: PLANTA | BD20: PLANTA
A21: Entregado | B21: 1379 | C21: ETP | D21: MAURICIO VALDIVIA | E21: ALJIBE | F21: 20 M³ INOX | G21: VOLVO | H21: VM 330 | I21: 180536 | J21: 26500000 | K21: 1 | L21: 5 | M21: OK | N21: 44746 | O21: 1 | P21: OK | Q21: - | R21: OK | S21: 1 | T21: OK | U21: 5.5 | V21: OK | W21: 6.5 | X21: OK | Y21: 1 | Z21: OK | AA21: 5.5 | AB21: OK | AC21: 3 | BB21: 6 GL | BC21: PLANTA | BD21: PLANTA
P22: - | Q22: - | R22: - | S22: - | T22: - | U22: - | V22: - | W22: - | X22: - | Y22: - | Z22: - | AA22: - | AB22: - | AC22: -
P23: - | Q23: - | R23: - | S23: - | T23: - | U23: - | V23: - | W23: - | X23: - | Y23: - | Z23: - | AA23: - | AB23: - | AC23: -
P24: - | Q24: - | R24: - | S24: - | T24: - | U24: - | V24: - | W24: - | X24: - | Y24: - | Z24: - | AA24: - | AB24: - | AC24: -
P25: - | Q25: - | R25: - | S25: - | T25: - | U25: - | V25: - | W25: - | X25: - | Y25: - | Z25: - | AA25: - | AB25: - | AC25: -
P26: - | Q26: - | R26: - | S26: - | T26: - | U26: - | V26: - | W26: - | X26: - | Y26: - | Z26: - | AA26: - | AB26: - | AC26: -
P27: - | Q27: - | R27: - | S27: - | T27: - | U27: - | V27: - | W27: - | X27: - | Y27: - | Z27: - | AA27: - | AB27: - | AC27: -
P28: - | Q28: - | R28: - | S28: - | T28: - | U28: - | V28: - | W28: - | X28: - | Y28: - | Z28: - | AA28: - | AB28: - | AC28: -
P29: - | Q29: - | R29: - | S29: - | T29: - | U29: - | V29: - | W29: - | X29: - | Y29: - | Z29: - | AA29: - | AB29: - | AC29: -
P30: - | Q30: - | R30: - | S30: - | T30: - | U30: - | V30: - | W30: - | X30: - | Y30: - | Z30: - | AA30: - | AB30: - | AC30: -
P31: - | Q31: - | R31: - | S31: - | T31: - | U31: - | V31: - | W31: - | X31: - | Y31: - | Z31: - | AA31: - | AB31: - | AC31: -
P32: - | Q32: - | R32: - | S32: - | T32: - | U32: - | V32: - | W32: - | X32: - | Y32: - | Z32: - | AA32: - | AB32: - | AC32: -
P33: - | Q33: - | R33: - | S33: - | T33: - | U33: - | V33: - | W33: - | X33: - | Y33: - | Z33: - | AA33: - | AB33: - | AC33: -
... P40: - | Q40: - | R40: - | S40: - | T40: - | U40: - | V40: - | W40: - | X40: - | Y40: - | Z40: - | AA40: - | AB40: - | AC40: -
